1|bot-api  | Require stack:
1|bot-api  | - /home/ubuntu/bot-api/dist/main.js
1|bot-api  |     at Function.Module._resolveFilename (node:internal/modules/cjs/loader:985:15)
1|bot-api  |     at Module.Hook._require.Module.require (/home/ubuntu/.nvm/versions/node/v16.18.1/lib/node_modules/pm2/node_modules/require-in-the-middle/index.js:81:25)
1|bot-api  |     at require (node:internal/modules/cjs/helpers:103:18)
1|bot-api  |     at Object.<anonymous> (/home/ubuntu/bot-api/src/main.ts:1:1)
1|bot-api  |     at Module._compile (node:internal/modules/cjs/loader:1155:14)
1|bot-api  |     at Object.Module._extensions..js (node:internal/modules/cjs/loader:1209:10)
1|bot-api  |     at Module.load (node:internal/modules/cjs/loader:1033:32)
1|bot-api  |     at Function.Module._load (node:internal/modules/cjs/loader:868:12)
1|bot-api  |     at Object.<anonymous> (/home/ubuntu/.nvm/versions/node/v16.18.1/lib/node_modules/pm2/lib/ProcessContainerFork.js:33:23)
1|bot-api  |     at Module._compile (node:internal/modules/cjs/loader:1155:14) {
1|bot-api  |   code: 'MODULE_NOT_FOUND',
1|bot-api  |   requireStack: [ '/home/ubuntu/bot-api/dist/main.js' ]
1|bot-api  | }

/home/ubuntu/.pm2/logs/bot-error.log last 15 lines:
0|bot      |   File "/home/ubuntu/bot_s/bot.py", line 59, in start_button
0|bot      |     user_stat = user_check(update.message.chat.id)
0|bot      |   File "/home/ubuntu/bot_s/requests_data.py", line 5, in user_check
0|bot      |     req = requests.get(
0|bot      |   File "/usr/lib/python3/dist-packages/requests/api.py", line 76, in get
0|bot      |     return request('get', url, params=params, **kwargs)
0|bot      |   File "/usr/lib/python3/dist-packages/requests/api.py", line 61, in request
0|bot      |     return session.request(method=method, url=url, **kwargs)
0|bot      |   File "/usr/lib/python3/dist-packages/requests/sessions.py", line 544, in request
0|bot      |     resp = self.send(prep, **send_kwargs)
0|bot      |   File "/usr/lib/python3/dist-packages/requests/sessions.py", line 657, in send
0|bot      |     r = adapter.send(request, **kwargs)
0|bot      |   File "/usr/lib/python3/dist-packages/requests/adapters.py", line 516, in send
0|bot      |     raise ConnectionError(e, request=request)
0|bot      | requests.exceptions.ConnectionError: HTTPConnectionPool(host='localhost', port=3001): Max retries exceeded with url: /check?idUser=2103889158 (Caused by NewConnectionError('<urllib3.connection.HTTPConnection object at 0x7fb7ab677010>: Failed to establish a new connection: [Errno 111] Connection refused'))